Traceback (most recent call last):
  File "/usr/local/lib/python3.8/dist-packages/jupyter_cache/executors/utils.py", line 51, in single_nb_execution
    executenb(
  File "/usr/local/lib/python3.8/dist-packages/nbclient/client.py", line 1204, in execute
    return NotebookClient(nb=nb, resources=resources, km=km, **kwargs).execute()
  File "/usr/local/lib/python3.8/dist-packages/nbclient/util.py", line 84, in wrapped
    return just_run(coro(*args, **kwargs))
  File "/usr/local/lib/python3.8/dist-packages/nbclient/util.py", line 62, in just_run
    return loop.run_until_complete(coro)
  File "/usr/lib/python3.8/asyncio/base_events.py", line 616, in run_until_complete
    return future.result()
  File "/usr/local/lib/python3.8/dist-packages/nbclient/client.py", line 663, in async_execute
    await self.async_execute_cell(
  File "/usr/local/lib/python3.8/dist-packages/nbclient/client.py", line 965, in async_execute_cell
    await self._check_raise_for_error(cell, cell_index, exec_reply)
  File "/usr/local/lib/python3.8/dist-packages/nbclient/client.py", line 862, in _check_raise_for_error
    raise CellExecutionError.from_cell_and_msg(cell, exec_reply_content)
nbclient.exceptions.CellExecutionError: An error occurred while executing the following cell:
------------------
    from functions import *
    collect_tune_and_predict('DOT1-USD',n_ahead = 365)
------------------

[0;31m---------------------------------------------------------------------------[0m
[0;31mValueError[0m                                Traceback (most recent call last)
Input [0;32mIn [1][0m, in [0;36m<cell line: 2>[0;34m()[0m
[1;32m      1[0m [38;5;28;01mfrom[39;00m [38;5;21;01mfunctions[39;00m [38;5;28;01mimport[39;00m [38;5;241m*[39m
[0;32m----> 2[0m [43mcollect_tune_and_predict[49m[43m([49m[38;5;124;43m'[39;49m[38;5;124;43mDOT1-USD[39;49m[38;5;124;43m'[39;49m[43m,[49m[43mn_ahead[49m[43m [49m[38;5;241;43m=[39;49m[43m [49m[38;5;241;43m365[39;49m[43m)[49m

File [0;32m/github/workspace/pycoins/coins/fbprophet/functions.py:89[0m, in [0;36mcollect_tune_and_predict[0;34m(item, n_ahead)[0m
[1;32m     87[0m [38;5;28;01mfor[39;00m params [38;5;129;01min[39;00m all_params:
[1;32m     88[0m     [38;5;28;01mwith[39;00m suppress_stdout_stderr():
[0;32m---> 89[0m         m [38;5;241m=[39m [43mProphet[49m[43m([49m[38;5;241;43m*[39;49m[38;5;241;43m*[39;49m[43mparams[49m[43m)[49m[38;5;241;43m.[39;49m[43mfit[49m[43m([49m[43mdata[49m[43m)[49m  [38;5;66;03m# Fit model with given params[39;00m
[1;32m     90[0m         df_cv [38;5;241m=[39m cross_validation(m, cutoffs[38;5;241m=[39mcutoffs, horizon[38;5;241m=[39m[38;5;124m'[39m[38;5;124m30 days[39m[38;5;124m'[39m, parallel[38;5;241m=[39m[38;5;124m"[39m[38;5;124mprocesses[39m[38;5;124m"[39m)
[1;32m     91[0m         df_p [38;5;241m=[39m performance_metrics(df_cv, rolling_window[38;5;241m=[39m[38;5;241m1[39m)

File [0;32m/usr/local/lib/python3.8/dist-packages/fbprophet/forecaster.py:1108[0m, in [0;36mProphet.fit[0;34m(self, df, **kwargs)[0m
[1;32m   1106[0m history [38;5;241m=[39m df[df[[38;5;124m'[39m[38;5;124my[39m[38;5;124m'[39m][38;5;241m.[39mnotnull()][38;5;241m.[39mcopy()
[1;32m   1107[0m [38;5;28;01mif[39;00m history[38;5;241m.[39mshape[[38;5;241m0[39m] [38;5;241m<[39m [38;5;241m2[39m:
[0;32m-> 1108[0m     [38;5;28;01mraise[39;00m [38;5;167;01mValueError[39;00m([38;5;124m'[39m[38;5;124mDataframe has less than 2 non-NaN rows.[39m[38;5;124m'[39m)
[1;32m   1109[0m [38;5;28mself[39m[38;5;241m.[39mhistory_dates [38;5;241m=[39m pd[38;5;241m.[39mto_datetime(pd[38;5;241m.[39mSeries(df[[38;5;124m'[39m[38;5;124mds[39m[38;5;124m'[39m][38;5;241m.[39munique(), name[38;5;241m=[39m[38;5;124m'[39m[38;5;124mds[39m[38;5;124m'[39m))[38;5;241m.[39msort_values()
[1;32m   1111[0m history [38;5;241m=[39m [38;5;28mself[39m[38;5;241m.[39msetup_dataframe(history, initialize_scales[38;5;241m=[39m[38;5;28;01mTrue[39;00m)

[0;31mValueError[0m: Dataframe has less than 2 non-NaN rows.
ValueError: Dataframe has less than 2 non-NaN rows.

